<?xml version="1.0" encoding="utf-8"?>
<!-- =================================================================================== -->
<!-- |    This document was autogenerated by xacro from rbkairos_base.urdf.xacro       | -->
<!-- |    EDITING THIS FILE BY HAND IS NOT RECOMMENDED                                 | -->
<!-- =================================================================================== -->
<robot name="rbkairos">
  <!-- ***************** -->
  <!-- Imported elements -->
  <!-- ***************** -->
  <!-- ***************** -->
  <!-- Imported elements -->
  <!-- ***************** -->
  <!-- First we import all posible elements defined in the urdf.xacro files. All these elements are defined as macro:xacros -->
  <gazebo reference="base_footprint">
    <material>Gazebo/Green</material>
  </gazebo>
  <!-- in kg-->
  <!-- in kg-->
  <!-- source en.wikipedia.org/wiki/List_of_moments_of_inertia-->
  <!-- This file unifies all sensors that can be used on simulation, defined as xacro:macros -->
  <!-- Includes -->
  <!-- *************** -->
  <!-- Robots Elements -->
  <!-- *************** -->
  <!-- Here we create the robot elements using the xacro:macros imported at the beggining of this file -->
  <link name="robotbase_footprint">
    <visual>
      <origin rpy="0 0 0" xyz="0 0 0"/>
      <geometry>
        <box size="0.001 0.001 0.001"/>
      </geometry>
    </visual>
  </link>
  <joint name="robotbase_footprint_joint" type="fixed">
    <origin rpy="0 0 0" xyz="0 0 0.127"/>
    <!-- ${wheel_radius} property must be defined inside wheel description -->
    <parent link="robotbase_footprint"/>
    <child link="robotbase_link"/>
  </joint>
  <!-- BASE_LINK -->
  <link name="robotbase_link">
    <inertial>
      <mass value="125.0"/>
      <origin xyz="0 0 0"/>
      <inertia ixx="1.391" ixy="0.004" ixz="0.0" iyy="6.853" iyz="0.0" izz="6.125"/>
    </inertial>
    <visual>
      <origin rpy="0 0 0" xyz="0 0 0"/>
      <geometry>
        <mesh filename="package://summit_xl_description/meshes/bases/xls/summit_xls_chassis.stl"/>
      </geometry>
      <material name="black">
        <color rgba="0.0 0.0 0.0 1"/>
      </material>
    </visual>
    <collision>
      <origin rpy="0 0 0 " xyz="0 0 0"/>
      <geometry>
        <mesh filename="package://summit_xl_description/meshes/bases/xls/summit_xls_chassis.dae"/>
      </geometry>
    </collision>
  </link>
  <gazebo reference="robotbase_link">
    <material>Gazebo/Black</material>
  </gazebo>
  <!-- CHAPAS INOX TAPAS -->
  <link name="robotbase_chapa">
    <visual>
      <origin rpy="0 0 0" xyz="0 0 0"/>
      <geometry>
        <mesh filename="package://summit_xl_description/meshes/bases/xls/summit_xls_chapas_inox_tapas.stl"/>
      </geometry>
      <material name="darkgrey">
        <color rgba="0.5 0.5 0.5 1"/>
      </material>
    </visual>
  </link>
  <joint name="robotbase_tapa_joint" type="fixed">
    <origin rpy="0 0 0" xyz="0.0 0 0.38062"/>
    <parent link="robotbase_link"/>
    <child link="robotbase_chapa"/>
  </joint>
  <!-- LOGO ROBOTNIK IZQUIERDO -->
  <link name="robotbase_logo_left">
    <visual>
      <origin rpy="0 0 0" xyz="0 0 0"/>
      <geometry>
        <mesh filename="package://summit_xl_description/meshes/bases/xls/robotnik_logo_chasis.stl"/>
      </geometry>
      <material name="darkgrey">
        <color rgba="0.5 0.5 0.5 1"/>
      </material>
    </visual>
  </link>
  <joint name="robotbase_logo_left_joint" type="fixed">
    <origin rpy="0 0 0" xyz="0.0 0.28931 0.29062"/>
    <parent link="robotbase_link"/>
    <child link="robotbase_logo_left"/>
  </joint>
  <!-- LOGO ROBOTNIK DERECHO -->
  <link name="robotbase_logo_right">
    <visual>
      <origin rpy="0 0 0" xyz="0 0 0"/>
      <geometry>
        <mesh filename="package://summit_xl_description/meshes/bases/xls/robotnik_logo_chasis.stl"/>
      </geometry>
      <material name="darkgrey">
        <color rgba="0.5 0.5 0.5 1"/>
      </material>
    </visual>
  </link>
  <joint name="robotbase_logo_right_joint" type="fixed">
    <origin rpy="0 0 3.14159265359" xyz="0.0 -0.28931 0.29062"/>
    <parent link="robotbase_link"/>
    <child link="robotbase_logo_right"/>
  </joint>
  <!-- LOGO ROBOTNIK FRONTAL -->
  <link name="robotbase_logo_front">
    <visual>
      <origin rpy="0 0 0" xyz="0 0 0"/>
      <geometry>
        <mesh filename="package://summit_xl_description/meshes/bases/xls/robotnik_logo_chasis.stl"/>
      </geometry>
      <material name="darkgrey">
        <color rgba="0.5 0.5 0.5 1"/>
      </material>
    </visual>
  </link>
  <joint name="robotbase_logo_front_joint" type="fixed">
    <origin rpy="0 0 -1.57079632679" xyz="0.345 0.0 0.0"/>
    <parent link="robotbase_link"/>
    <child link="robotbase_logo_front"/>
  </joint>
  <!-- LOGO ROBOTNIK TRASERO -->
  <link name="robotbase_logo_rear">
    <visual>
      <origin rpy="0 0 0" xyz="0 0 0"/>
      <geometry>
        <mesh filename="package://summit_xl_description/meshes/bases/xls/robotnik_logo_chasis.stl"/>
      </geometry>
      <material name="darkgrey">
        <color rgba="0.5 0.5 0.5 1"/>
      </material>
    </visual>
  </link>
  <joint name="robotbase_logo_rear_joint" type="fixed">
    <origin rpy="0 0 1.57079632679" xyz="-0.345 0.0 0.0"/>
    <parent link="robotbase_link"/>
    <child link="robotbase_logo_rear"/>
  </joint>
  <!-- DOCKING CONTACT -->
  <link name="robotbase_docking_contact">
    </link>
  <joint name="robotbase_docking_joint" type="fixed">
    <origin rpy="0 0 0" xyz="0.35 0 0.09"/>
    <parent link="robotbase_link"/>
    <child link="robotbase_docking_contact"/>
  </joint>
  <joint name="robotfront_right_wheel_joint" type="continuous">
    <parent link="robotbase_link"/>
    <child link="robotfront_right_wheel_link"/>
    <origin rpy="0 0 0" xyz="0.2225 -0.2045 0.0"/>
    <axis rpy="0 0 0" xyz="0 1 0"/>
    <limit effort="100" velocity="100"/>
    <joint_properties damping="0.0" friction="0.0"/>
  </joint>
  <link name="robotfront_right_wheel_link">
    <visual>
      <origin rpy="0 0 0" xyz="0 0 0"/>
      <geometry>
        <mesh filename="package://summit_xl_description/meshes/wheels/omni_wheel_2.dae"/>
      </geometry>
      <material name="darkgrey">
        <color rgba="0.2 0.2 0.2 1"/>
      </material>
    </visual>
    <collision>
      <origin rpy="1.57079632679 0 0" xyz="0 0 0"/>
      <geometry>
        <!--sphere radius="${omni_wheel_radius}" /-->
        <!--
          <xacro:if value="${reflect}">
              <mesh filename="package://summit_xl_description/meshes/wheels/omni_wheel_1.dae" />
          </xacro:if>
          <xacro:unless value="${reflect}">
              <mesh filename="package://summit_xl_description/meshes/wheels/omni_wheel_2.dae" />
					</xacro:unless>
-->
        <cylinder length="0.087" radius="0.127"/>
        <!-- sphere radius="${omni_wheel_radius}"/-->
      </geometry>
    </collision>
    <inertial>
      <mass value="6.5"/>
      <origin xyz="0 0 0"/>
      <inertia ixx="0.0303095" ixy="0" ixz="0" iyy="0.05241925" iyz="0" izz="0.0303095"/>
    </inertial>
  </link>
  <!-- Transmission is important to link the joints and the controller (see summit_xl_control/config/summit_xl_control.yaml)-->
  <transmission name="robotfront_right_wheel_joint_trans">
    <type>transmission_interface/SimpleTransmission</type>
    <joint name="robotfront_right_wheel_joint">
      <hardwareInterface>hardware_interface/VelocityJointInterface</hardwareInterface>
    </joint>
    <actuator name="robotfront_right_wheel_joint_motor">
      <mechanicalReduction>1</mechanicalReduction>
    </actuator>
  </transmission>
  <gazebo reference="robotfront_right_wheel_link">
    <mu1 value="0.0"/>
    <mu2 value="0.0"/>
    <kp value="10000000.0"/>
    <kd value="1.0"/>
    <fdir1 value="1 0 0"/>
    <turnGravityOff>false</turnGravityOff>
  </gazebo>
  <joint name="robotfront_left_wheel_joint" type="continuous">
    <parent link="robotbase_link"/>
    <child link="robotfront_left_wheel_link"/>
    <origin rpy="0 0 0" xyz="0.2225 0.2045 0.0"/>
    <axis rpy="0 0 0" xyz="0 1 0"/>
    <limit effort="100" velocity="100"/>
    <joint_properties damping="0.0" friction="0.0"/>
  </joint>
  <link name="robotfront_left_wheel_link">
    <visual>
      <origin rpy="0 0 0" xyz="0 0 0"/>
      <geometry>
        <mesh filename="package://summit_xl_description/meshes/wheels/omni_wheel_1.dae"/>
      </geometry>
      <material name="darkgrey">
        <color rgba="0.2 0.2 0.2 1"/>
      </material>
    </visual>
    <collision>
      <origin rpy="1.57079632679 0 0" xyz="0 0 0"/>
      <geometry>
        <!--sphere radius="${omni_wheel_radius}" /-->
        <!--
          <xacro:if value="${reflect}">
              <mesh filename="package://summit_xl_description/meshes/wheels/omni_wheel_1.dae" />
          </xacro:if>
          <xacro:unless value="${reflect}">
              <mesh filename="package://summit_xl_description/meshes/wheels/omni_wheel_2.dae" />
					</xacro:unless>
-->
        <cylinder length="0.087" radius="0.127"/>
        <!-- sphere radius="${omni_wheel_radius}"/-->
      </geometry>
    </collision>
    <inertial>
      <mass value="6.5"/>
      <origin xyz="0 0 0"/>
      <inertia ixx="0.0303095" ixy="0" ixz="0" iyy="0.05241925" iyz="0" izz="0.0303095"/>
    </inertial>
  </link>
  <!-- Transmission is important to link the joints and the controller (see summit_xl_control/config/summit_xl_control.yaml)-->
  <transmission name="robotfront_left_wheel_joint_trans">
    <type>transmission_interface/SimpleTransmission</type>
    <joint name="robotfront_left_wheel_joint">
      <hardwareInterface>hardware_interface/VelocityJointInterface</hardwareInterface>
    </joint>
    <actuator name="robotfront_left_wheel_joint_motor">
      <mechanicalReduction>1</mechanicalReduction>
    </actuator>
  </transmission>
  <gazebo reference="robotfront_left_wheel_link">
    <mu1 value="0.0"/>
    <mu2 value="0.0"/>
    <kp value="10000000.0"/>
    <kd value="1.0"/>
    <fdir1 value="1 0 0"/>
    <turnGravityOff>false</turnGravityOff>
  </gazebo>
  <joint name="robotback_left_wheel_joint" type="continuous">
    <parent link="robotbase_link"/>
    <child link="robotback_left_wheel_link"/>
    <origin rpy="0 0 0" xyz="-0.2225 0.2045 0.0"/>
    <axis rpy="0 0 0" xyz="0 1 0"/>
    <limit effort="100" velocity="100"/>
    <joint_properties damping="0.0" friction="0.0"/>
  </joint>
  <link name="robotback_left_wheel_link">
    <visual>
      <origin rpy="0 0 0" xyz="0 0 0"/>
      <geometry>
        <mesh filename="package://summit_xl_description/meshes/wheels/omni_wheel_1.dae"/>
      </geometry>
      <material name="darkgrey">
        <color rgba="0.2 0.2 0.2 1"/>
      </material>
    </visual>
    <collision>
      <origin rpy="1.57079632679 0 0" xyz="0 0 0"/>
      <geometry>
        <!--sphere radius="${omni_wheel_radius}" /-->
        <!--
          <xacro:if value="${reflect}">
              <mesh filename="package://summit_xl_description/meshes/wheels/omni_wheel_1.dae" />
          </xacro:if>
          <xacro:unless value="${reflect}">
              <mesh filename="package://summit_xl_description/meshes/wheels/omni_wheel_2.dae" />
					</xacro:unless>
-->
        <cylinder length="0.087" radius="0.127"/>
        <!-- sphere radius="${omni_wheel_radius}"/-->
      </geometry>
    </collision>
    <inertial>
      <mass value="6.5"/>
      <origin xyz="0 0 0"/>
      <inertia ixx="0.0303095" ixy="0" ixz="0" iyy="0.05241925" iyz="0" izz="0.0303095"/>
    </inertial>
  </link>
  <!-- Transmission is important to link the joints and the controller (see summit_xl_control/config/summit_xl_control.yaml)-->
  <transmission name="robotback_left_wheel_joint_trans">
    <type>transmission_interface/SimpleTransmission</type>
    <joint name="robotback_left_wheel_joint">
      <hardwareInterface>hardware_interface/VelocityJointInterface</hardwareInterface>
    </joint>
    <actuator name="robotback_left_wheel_joint_motor">
      <mechanicalReduction>1</mechanicalReduction>
    </actuator>
  </transmission>
  <gazebo reference="robotback_left_wheel_link">
    <mu1 value="0.0"/>
    <mu2 value="0.0"/>
    <kp value="10000000.0"/>
    <kd value="1.0"/>
    <fdir1 value="1 0 0"/>
    <turnGravityOff>false</turnGravityOff>
  </gazebo>
  <joint name="robotback_right_wheel_joint" type="continuous">
    <parent link="robotbase_link"/>
    <child link="robotback_right_wheel_link"/>
    <origin rpy="0 0 0" xyz="-0.2225 -0.2045 0.0"/>
    <axis rpy="0 0 0" xyz="0 1 0"/>
    <limit effort="100" velocity="100"/>
    <joint_properties damping="0.0" friction="0.0"/>
  </joint>
  <link name="robotback_right_wheel_link">
    <visual>
      <origin rpy="0 0 0" xyz="0 0 0"/>
      <geometry>
        <mesh filename="package://summit_xl_description/meshes/wheels/omni_wheel_2.dae"/>
      </geometry>
      <material name="darkgrey">
        <color rgba="0.2 0.2 0.2 1"/>
      </material>
    </visual>
    <collision>
      <origin rpy="1.57079632679 0 0" xyz="0 0 0"/>
      <geometry>
        <!--sphere radius="${omni_wheel_radius}" /-->
        <!--
          <xacro:if value="${reflect}">
              <mesh filename="package://summit_xl_description/meshes/wheels/omni_wheel_1.dae" />
          </xacro:if>
          <xacro:unless value="${reflect}">
              <mesh filename="package://summit_xl_description/meshes/wheels/omni_wheel_2.dae" />
					</xacro:unless>
-->
        <cylinder length="0.087" radius="0.127"/>
        <!-- sphere radius="${omni_wheel_radius}"/-->
      </geometry>
    </collision>
    <inertial>
      <mass value="6.5"/>
      <origin xyz="0 0 0"/>
      <inertia ixx="0.0303095" ixy="0" ixz="0" iyy="0.05241925" iyz="0" izz="0.0303095"/>
    </inertial>
  </link>
  <!-- Transmission is important to link the joints and the controller (see summit_xl_control/config/summit_xl_control.yaml)-->
  <transmission name="robotback_right_wheel_joint_trans">
    <type>transmission_interface/SimpleTransmission</type>
    <joint name="robotback_right_wheel_joint">
      <hardwareInterface>hardware_interface/VelocityJointInterface</hardwareInterface>
    </joint>
    <actuator name="robotback_right_wheel_joint_motor">
      <mechanicalReduction>1</mechanicalReduction>
    </actuator>
  </transmission>
  <gazebo reference="robotback_right_wheel_link">
    <mu1 value="0.0"/>
    <mu2 value="0.0"/>
    <kp value="10000000.0"/>
    <kd value="1.0"/>
    <fdir1 value="1 0 0"/>
    <turnGravityOff>false</turnGravityOff>
  </gazebo>
  <joint name="robotimu_joint" type="fixed">
    <axis xyz="1 0 0"/>
    <!--origin xyz="0 0 0.2825"/-->
    <origin rpy="0 0 0" xyz="0.127 -0.129 0.212"/>
    <parent link="robotbase_link"/>
    <child link="robotimu_link"/>
  </joint>
  <link name="robotimu_link">
    <inertial>
      <origin rpy="0 0 0" xyz="0.0 0 0.01"/>
      <mass value="0.05"/>
      <inertia ixx="3.33333333333e-06" ixy="0" ixz="0" iyy="3.33333333333e-06" iyz="0" izz="3.33333333333e-06"/>
    </inertial>
    <visual>
      <origin rpy="0 0 0" xyz="0 0 0"/>
      <geometry>
        <box size="0.001 0.001 0.001"/>
      </geometry>
    </visual>
    <collision>
      <origin rpy="0 0 0" xyz="0 0 0"/>
      <geometry>
        <box size=".001 .001 .001"/>
      </geometry>
    </collision>
  </link>
  <gazebo>
    <plugin filename="libhector_gazebo_ros_imu.so" name="robotimu_controller">
      <alwaysOn>true</alwaysOn>
      <topicName>imu/data</topicName>
      <serviceName>robotimuimu/service</serviceName>
      <bodyName>robotimu_link</bodyName>
      <frameId>robotimu_link</frameId>
      <updateRate>50.0</updateRate>
      <gaussianNoise>0.00</gaussianNoise>
      <yawOffset>0.0</yawOffset>
      <yawDrift>0.0</yawDrift>
      <yawGaussianNoise>0.0</yawGaussianNoise>
      <!-- angular velocities parameters -->
      <rateOffset>0.0 0.0 0.0</rateOffset>
      <rateDrift>0.0 0.0 0.0</rateDrift>
      <rateGaussianNoise>0.0 0.0 0.0</rateGaussianNoise>
      <!-- linear accelerations parameters -->
      <accelOffset>0.0 0.0 0.0</accelOffset>
      <accelDrift>0.0 0.0 0.0</accelDrift>
      <accelGaussianNoise>0.0 0.0 0.0</accelGaussianNoise>
    </plugin>
  </gazebo>
  <joint name="robotfront_laser_base_joint" type="fixed">
    <origin rpy="0 -3.14159265359 2.35619449019" xyz="0.2865 -0.20894 0.2973"/>
    <parent link="robotbase_link"/>
    <child link="robotfront_laser_base_link"/>
    <limit effort="100" lower="0.0" upper="0.0" velocity="100"/>
  </joint>
  <link name="robotfront_laser_base_link">
    <collision>
      <origin rpy="0 0 0" xyz="0 0 0"/>
      <geometry>
        <!--<box size="0.106 0.094 0.152"/>-->
        <!--<cylinder radius="0.058" length="0.152"/>-->
        <mesh filename="package://robotnik_sensors/meshes/sick_s300.dae"/>
      </geometry>
    </collision>
    <visual>
      <origin rpy="0 0 0" xyz="0 0 0"/>
      <geometry>
        <mesh filename="package://robotnik_sensors/meshes/sick_s300.dae"/>
      </geometry>
    </visual>
    <!--inertial>
			<mass value="1e-5" />
			<origin xyz="0 0 0" rpy="0 0 0"/>
			<inertia ixx="1e-6" ixy="0" ixz="0" iyy="1e-6" iyz="0" izz="1e-6" />
		</inertial-->
    <inertial>
      <mass value="1.2"/>
      <origin rpy="0 0 0" xyz="0 0.0 0.0751"/>
      <inertia ixx="0.003434" ixy="0" ixz="0" iyy="0.0033508" iyz="0" izz="0.002164"/>
      <!--inertia ixx="0.0002708333" ixy="0" ixz="0" iyy="0.0002708333" iyz="0" izz="0.00009434" /-->
    </inertial>
  </link>
  <joint name="robotfront_laser_joint" type="fixed">
    <parent link="robotfront_laser_base_link"/>
    <child link="robotfront_laser_link"/>
    <origin rpy="0 0 0" xyz="0.0 0 0.116"/>
  </joint>
  <link name="robotfront_laser_link"/>
  <gazebo reference="robotfront_laser_link">
    <sensor name="robotfront_laser_sensor" type="gpu_ray">
      <pose>0 0 0 0 0 0</pose>
      <visualize>false</visualize>
      <update_rate>12.5</update_rate>
      <ray>
        <scan>
          <horizontal>
            <samples>541</samples>
            <resolution>1</resolution>
            <min_angle>-2.3562</min_angle>
            <max_angle>2.3562</max_angle>
          </horizontal>
        </scan>
        <range>
          <min>0.10</min>
          <max>30.0</max>
          <resolution>0.03</resolution>
        </range>
        <noise>
          <type>gaussian</type>
          <mean>0.0</mean>
          <stddev>0.03</stddev>
        </noise>
      </ray>
      <plugin filename="libgazebo_ros_gpu_laser.so" name="robotfront_laser_controller">
        <topicName>front_laser/scan</topicName>
        <frameName>/robotfront_laser_link</frameName>
        <!-- if not global (leading /) sets the current namespace as a prefix (/ns/name_laser_link) -->
      </plugin>
    </sensor>
  </gazebo>
  <joint name="robotrear_laser_base_joint" type="fixed">
    <origin rpy="0 -3.14159265359 -0.785398163397" xyz="-0.2865 0.20894 0.2973"/>
    <parent link="robotbase_link"/>
    <child link="robotrear_laser_base_link"/>
    <limit effort="100" lower="0.0" upper="0.0" velocity="100"/>
  </joint>
  <link name="robotrear_laser_base_link">
    <collision>
      <origin rpy="0 0 0" xyz="0 0 0"/>
      <geometry>
        <!--<box size="0.106 0.094 0.152"/>-->
        <!--<cylinder radius="0.058" length="0.152"/>-->
        <mesh filename="package://robotnik_sensors/meshes/sick_s300.dae"/>
      </geometry>
    </collision>
    <visual>
      <origin rpy="0 0 0" xyz="0 0 0"/>
      <geometry>
        <mesh filename="package://robotnik_sensors/meshes/sick_s300.dae"/>
      </geometry>
    </visual>
    <!--inertial>
			<mass value="1e-5" />
			<origin xyz="0 0 0" rpy="0 0 0"/>
			<inertia ixx="1e-6" ixy="0" ixz="0" iyy="1e-6" iyz="0" izz="1e-6" />
		</inertial-->
    <inertial>
      <mass value="1.2"/>
      <origin rpy="0 0 0" xyz="0 0.0 0.0751"/>
      <inertia ixx="0.003434" ixy="0" ixz="0" iyy="0.0033508" iyz="0" izz="0.002164"/>
      <!--inertia ixx="0.0002708333" ixy="0" ixz="0" iyy="0.0002708333" iyz="0" izz="0.00009434" /-->
    </inertial>
  </link>
  <joint name="robotrear_laser_joint" type="fixed">
    <parent link="robotrear_laser_base_link"/>
    <child link="robotrear_laser_link"/>
    <origin rpy="0 0 0" xyz="0.0 0 0.116"/>
  </joint>
  <link name="robotrear_laser_link"/>
  <gazebo reference="robotrear_laser_link">
    <sensor name="robotrear_laser_sensor" type="gpu_ray">
      <pose>0 0 0 0 0 0</pose>
      <visualize>false</visualize>
      <update_rate>12.5</update_rate>
      <ray>
        <scan>
          <horizontal>
            <samples>541</samples>
            <resolution>1</resolution>
            <min_angle>-2.3562</min_angle>
            <max_angle>2.3562</max_angle>
          </horizontal>
        </scan>
        <range>
          <min>0.10</min>
          <max>30.0</max>
          <resolution>0.03</resolution>
        </range>
        <noise>
          <type>gaussian</type>
          <mean>0.0</mean>
          <stddev>0.03</stddev>
        </noise>
      </ray>
      <plugin filename="libgazebo_ros_gpu_laser.so" name="robotrear_laser_controller">
        <topicName>rear_laser/scan</topicName>
        <frameName>/robotrear_laser_link</frameName>
        <!-- if not global (leading /) sets the current namespace as a prefix (/ns/name_laser_link) -->
      </plugin>
    </sensor>
  </gazebo>
  <joint name="robotfront_rgbd_camera_joint" type="fixed">
    <origin rpy="0 0 0" xyz="0.3585 0.0 0.25062"/>
    <parent link="robotbase_link"/>
    <child link="robotfront_rgbd_camera_link"/>
  </joint>
  <link name="robotfront_rgbd_camera_link">
    <visual>
      <origin rpy="0 0 0" xyz="0 0 0"/>
      <geometry>
        <mesh filename="package://robotnik_sensors/meshes/orbbec_astra.dae"/>
      </geometry>
    </visual>
    <collision>
      <geometry>
        <mesh filename="package://robotnik_sensors/meshes/orbbec_astra.dae"/>
      </geometry>
    </collision>
    <inertial>
      <mass value="0.001"/>
      <origin xyz="0.0 0.0 0.0"/>
      <inertia ixx="2.34375e-06" ixy="0" ixz="0" iyy="2.08333333333e-07" iyz="0" izz="2.40208333333e-06"/>
    </inertial>
  </link>
  <joint name="robotfront_rgbd_camera_rgb_joint" type="fixed">
    <origin rpy="0.0 0.0 0.0" xyz="0.0 0.0125 0.0150"/>
    <parent link="robotfront_rgbd_camera_link"/>
    <child link="robotfront_rgbd_camera_rgb_frame"/>
  </joint>
  <link name="robotfront_rgbd_camera_rgb_frame">
    <inertial>
      <mass value="0.297"/>
      <origin xyz="-0.02 -0.0125 0.0"/>
      <inertia ixx="0.00069609375" ixy="0" ixz="0" iyy="6.1875e-05" iyz="0" izz="0.00071341875"/>
    </inertial>
  </link>
  <joint name="robotfront_rgbd_camera_rgb_optical_joint" type="fixed">
    <origin rpy="-1.57079632679 0 -1.57079632679" xyz="0.0 0.0 0.0"/>
    <parent link="robotfront_rgbd_camera_rgb_frame"/>
    <child link="robotfront_rgbd_camera_rgb_optical_frame"/>
  </joint>
  <link name="robotfront_rgbd_camera_rgb_optical_frame">
    <inertial>
      <mass value="0.001"/>
      <origin rpy="1.57079632679 0 1.57079632679" xyz="0 0 0"/>
      <inertia ixx="2.34375e-06" ixy="0" ixz="0" iyy="2.08333333333e-07" iyz="0" izz="2.40208333333e-06"/>
    </inertial>
  </link>
  <joint name="robotfront_rgbd_camera_depth_joint" type="fixed">
    <origin rpy="0 0 0" xyz="0.0 0.0375 0.0150"/>
    <parent link="robotfront_rgbd_camera_link"/>
    <child link="robotfront_rgbd_camera_depth_frame"/>
  </joint>
  <link name="robotfront_rgbd_camera_depth_frame">
    <inertial>
      <mass value="0.001"/>
      <origin xyz="0 0 0"/>
      <inertia ixx="2.34375e-06" ixy="0" ixz="0" iyy="2.08333333333e-07" iyz="0" izz="2.40208333333e-06"/>
    </inertial>
  </link>
  <joint name="robotfront_rgbd_camera_depth_optical_joint" type="fixed">
    <origin rpy="-1.57079632679 0 -1.57079632679" xyz="0 0 0"/>
    <parent link="robotfront_rgbd_camera_depth_frame"/>
    <child link="robotfront_rgbd_camera_depth_optical_frame"/>
  </joint>
  <link name="robotfront_rgbd_camera_depth_optical_frame">
    <inertial>
      <mass value="0.001"/>
      <origin xyz="0 0 0"/>
      <inertia ixx="2.34375e-06" ixy="0" ixz="0" iyy="2.08333333333e-07" iyz="0" izz="2.40208333333e-06"/>
    </inertial>
  </link>
  <gazebo reference="robotfront_rgbd_camera_link">
    <sensor name="robotfront_rgbd_camera_depth_sensor" type="depth">
      <always_on>true</always_on>
      <update_rate>20.0</update_rate>
      <camera>
        <horizontal_fov>1.0471975512</horizontal_fov>
        <image>
          <format>R8G8B8</format>
          <width>640</width>
          <height>480</height>
        </image>
        <clip>
          <near>0.05</near>
          <far>3.5</far>
        </clip>
      </camera>
      <plugin filename="libgazebo_ros_openni_kinect.so" name="robotfront_rgbd_camera_controller">
        <cameraName>front_rgbd_camera</cameraName>
        <alwaysOn>true</alwaysOn>
        <updateRate>10</updateRate>
        <imageTopicName>rgb/image_raw</imageTopicName>
        <depthImageTopicName>depth/image_raw</depthImageTopicName>
        <pointCloudTopicName>depth/points</pointCloudTopicName>
        <cameraInfoTopicName>rgb/camera_info</cameraInfoTopicName>
        <depthImageCameraInfoTopicName>depth/camera_info</depthImageCameraInfoTopicName>
        <frameName>/robotfront_rgbd_camera_depth_optical_frame</frameName>
        <baseline>0.1</baseline>
        <distortion_k1>0.0</distortion_k1>
        <distortion_k2>0.0</distortion_k2>
        <distortion_k3>0.0</distortion_k3>
        <distortion_t1>0.0</distortion_t1>
        <distortion_t2>0.0</distortion_t2>
        <pointCloudCutoff>0.4</pointCloudCutoff>
      </plugin>
    </sensor>
  </gazebo>
  <gazebo>
    <plugin filename="libgazebo_ros_control.so" name="ros_control">
      <robotParam>robot_description</robotParam>
      <controlPeriod>0.001</controlPeriod>
      <robotSimType>gazebo_ros_control/DefaultRobotHWSim</robotSimType>
      <legacyModeNS>true</legacyModeNS>
    </plugin>
  </gazebo>
</robot>
